Traceback (most recent call last):
  File "/home/lhs18285/miniconda3/envs/pangeo/lib/python3.9/site-packages/jupyter_cache/executors/utils.py", line 51, in single_nb_execution
    executenb(
  File "/home/lhs18285/miniconda3/envs/pangeo/lib/python3.9/site-packages/nbclient/client.py", line 1112, in execute
    return NotebookClient(nb=nb, resources=resources, km=km, **kwargs).execute()
  File "/home/lhs18285/miniconda3/envs/pangeo/lib/python3.9/site-packages/nbclient/util.py", line 74, in wrapped
    return just_run(coro(*args, **kwargs))
  File "/home/lhs18285/miniconda3/envs/pangeo/lib/python3.9/site-packages/nbclient/util.py", line 53, in just_run
    return loop.run_until_complete(coro)
  File "/home/lhs18285/miniconda3/envs/pangeo/lib/python3.9/asyncio/base_events.py", line 642, in run_until_complete
    return future.result()
  File "/home/lhs18285/miniconda3/envs/pangeo/lib/python3.9/site-packages/nbclient/client.py", line 553, in async_execute
    await self.async_execute_cell(
  File "/home/lhs18285/miniconda3/envs/pangeo/lib/python3.9/site-packages/nbclient/client.py", line 857, in async_execute_cell
    self._check_raise_for_error(cell, exec_reply)
  File "/home/lhs18285/miniconda3/envs/pangeo/lib/python3.9/site-packages/nbclient/client.py", line 760, in _check_raise_for_error
    raise CellExecutionError.from_cell_and_msg(cell, exec_reply_content)
nbclient.exceptions.CellExecutionError: An error occurred while executing the following cell:
------------------
import glob
import os
import urllib

import intake
from intake_zenodo_fetcher import download_zenodo_files_for_entry
import matplotlib.pyplot as plt
import xmltodict
import cv2

import tempfile

%matplotlib inline
------------------

[0;31m---------------------------------------------------------------------------[0m
[0;31mModuleNotFoundError[0m                       Traceback (most recent call last)
[0;32m<ipython-input-2-80aa76ba0cbd>[0m in [0;36m<module>[0;34m[0m
[1;32m      4[0m [0;34m[0m[0m
[1;32m      5[0m [0;32mimport[0m [0mintake[0m[0;34m[0m[0;34m[0m[0m
[0;32m----> 6[0;31m [0;32mfrom[0m [0mintake_zenodo_fetcher[0m [0;32mimport[0m [0mdownload_zenodo_files_for_entry[0m[0;34m[0m[0;34m[0m[0m
[0m[1;32m      7[0m [0;32mimport[0m [0mmatplotlib[0m[0;34m.[0m[0mpyplot[0m [0;32mas[0m [0mplt[0m[0;34m[0m[0;34m[0m[0m
[1;32m      8[0m [0;32mimport[0m [0mxmltodict[0m[0;34m[0m[0;34m[0m[0m

[0;32m~/miniconda3/envs/pangeo/lib/python3.9/site-packages/intake_zenodo_fetcher/__init__.py[0m in [0;36m<module>[0;34m[0m
[0;32m----> 1[0;31m [0;32mfrom[0m [0;34m.[0m[0mfetching[0m [0;32mimport[0m [0mdownload_zenodo_files_for_entry[0m[0;34m[0m[0;34m[0m[0m
[0m
[0;32m~/miniconda3/envs/pangeo/lib/python3.9/site-packages/intake_zenodo_fetcher/fetching.py[0m in [0;36m<module>[0;34m[0m
[1;32m      3[0m [0;32mimport[0m [0mos[0m[0;34m[0m[0;34m[0m[0m
[1;32m      4[0m [0;32mfrom[0m [0mpathlib[0m [0;32mimport[0m [0mPath[0m[0;34m[0m[0;34m[0m[0m
[0;32m----> 5[0;31m [0;32mimport[0m [0mpycurl[0m[0;34m[0m[0;34m[0m[0m
[0m[1;32m      6[0m [0;32mimport[0m [0mre[0m[0;34m[0m[0;34m[0m[0m
[1;32m      7[0m [0;32mimport[0m [0mrequests[0m[0;34m[0m[0;34m[0m[0m

[0;31mModuleNotFoundError[0m: No module named 'pycurl'
ModuleNotFoundError: No module named 'pycurl'

