Traceback (most recent call last):
  File "/home/lhs18285/miniconda3/envs/pangeo/lib/python3.9/site-packages/jupyter_cache/executors/utils.py", line 51, in single_nb_execution
    executenb(
  File "/home/lhs18285/miniconda3/envs/pangeo/lib/python3.9/site-packages/nbclient/client.py", line 1112, in execute
    return NotebookClient(nb=nb, resources=resources, km=km, **kwargs).execute()
  File "/home/lhs18285/miniconda3/envs/pangeo/lib/python3.9/site-packages/nbclient/util.py", line 74, in wrapped
    return just_run(coro(*args, **kwargs))
  File "/home/lhs18285/miniconda3/envs/pangeo/lib/python3.9/site-packages/nbclient/util.py", line 53, in just_run
    return loop.run_until_complete(coro)
  File "/home/lhs18285/miniconda3/envs/pangeo/lib/python3.9/asyncio/base_events.py", line 642, in run_until_complete
    return future.result()
  File "/home/lhs18285/miniconda3/envs/pangeo/lib/python3.9/site-packages/nbclient/client.py", line 553, in async_execute
    await self.async_execute_cell(
  File "/home/lhs18285/miniconda3/envs/pangeo/lib/python3.9/site-packages/nbclient/client.py", line 857, in async_execute_cell
    self._check_raise_for_error(cell, exec_reply)
  File "/home/lhs18285/miniconda3/envs/pangeo/lib/python3.9/site-packages/nbclient/client.py", line 760, in _check_raise_for_error
    raise CellExecutionError.from_cell_and_msg(cell, exec_reply_content)
nbclient.exceptions.CellExecutionError: An error occurred while executing the following cell:
------------------
username = input('Username: ')
password = getpass('Password: ')
    
fsspec.config.conf['https'] = dict(client_kwargs={'auth': aiohttp.BasicAuth(username, password)})

url = 'https://ladsweb.modaps.eosdis.nasa.gov/archive/allData/61/MOD021KM/2020/245/MOD021KM.A2020245.0840.061.2020245193036.hdf'
filename = url.split('/')[-1]
with fsspec.open(url) as f:
    with Path(filename).open('wb') as handle:
        handle.write(f.read())
------------------

[0;31m---------------------------------------------------------------------------[0m
[0;31mStdinNotImplementedError[0m                  Traceback (most recent call last)
[0;32m<ipython-input-3-a56d947ca123>[0m in [0;36m<module>[0;34m[0m
[0;32m----> 1[0;31m [0musername[0m [0;34m=[0m [0minput[0m[0;34m([0m[0;34m'Username: '[0m[0;34m)[0m[0;34m[0m[0;34m[0m[0m
[0m[1;32m      2[0m [0mpassword[0m [0;34m=[0m [0mgetpass[0m[0;34m([0m[0;34m'Password: '[0m[0;34m)[0m[0;34m[0m[0;34m[0m[0m
[1;32m      3[0m [0;34m[0m[0m
[1;32m      4[0m [0mfsspec[0m[0;34m.[0m[0mconfig[0m[0;34m.[0m[0mconf[0m[0;34m[[0m[0;34m'https'[0m[0;34m][0m [0;34m=[0m [0mdict[0m[0;34m([0m[0mclient_kwargs[0m[0;34m=[0m[0;34m{[0m[0;34m'auth'[0m[0;34m:[0m [0maiohttp[0m[0;34m.[0m[0mBasicAuth[0m[0;34m([0m[0musername[0m[0;34m,[0m [0mpassword[0m[0;34m)[0m[0;34m}[0m[0;34m)[0m[0;34m[0m[0;34m[0m[0m
[1;32m      5[0m [0;34m[0m[0m

[0;32m~/miniconda3/envs/pangeo/lib/python3.9/site-packages/ipykernel/kernelbase.py[0m in [0;36mraw_input[0;34m(self, prompt)[0m
[1;32m    855[0m         """
[1;32m    856[0m         [0;32mif[0m [0;32mnot[0m [0mself[0m[0;34m.[0m[0m_allow_stdin[0m[0;34m:[0m[0;34m[0m[0;34m[0m[0m
[0;32m--> 857[0;31m             raise StdinNotImplementedError(
[0m[1;32m    858[0m                 [0;34m"raw_input was called, but this frontend does not support input requests."[0m[0;34m[0m[0;34m[0m[0m
[1;32m    859[0m             )

[0;31mStdinNotImplementedError[0m: raw_input was called, but this frontend does not support input requests.
StdinNotImplementedError: raw_input was called, but this frontend does not support input requests.

